Workbook

Sheet Financials_Netflix
A1: Statement of Profit or Loss for the years ended 31 December
A2: Annual Data (USD millions) | B2: 2025-12-31 | C2: 2024-12-31 | D2: 2023-12-31 | E2: 2022-12-31 | F2: 2021-12-31
A3: Revenue | B3: 45183.04 | C3: 39000.96 | D3: 33723.3 | E3: 31615.55 | F3: 29697.84
A4: Cost Of Goods Sold | B4: 23275.33 | C4: 21038.46 | D4: 19715.37 | E4: 19168.29 | F4: 17332.68
A5: Gross Profit | B5: =B3-B4 -> 21907.71 | C5: 17962.5 | D5: 14007.93 | E5: 12447.27 | F5: 12365.16
A6: Research And Development Expenses | B6: 3391.39 | C6: 2925.295 | D6: 2675.758 | E6: 2711.041 | F6: 2273.885
A7: SG&A Expenses | B7: 5189.714 | C7: 4619.593 | D7: 4378.168 | E7: 4103.393 | F7: 3896.767
A8: Operating Expenses | B8: =B6+B7 -> 8581.104 | C8: =C6+C7 -> 7544.888 | D8: =D6+D7 -> 7053.926 | E8: =E6+E7 -> 6814.434 | F8: =F6+F7 -> 6170.652
A9: Operating Income | B9: =B5-B8 -> 13326.606 | C9: =C5-C8 -> 10417.612 | D9: =D5-D8 -> 6954.004 | E9: =E5-E8 -> 5632.836 | F9: =F5-F8 -> 6194.508
A10: Total Non-Operating Income/Expense | B10: -604.051 | C10: -451.957 | D10: -748.598 | E10: -368.902 | F10: -354.406
A11: Pre-Tax Income | B11: =B9+B10 -> 12722.555 | C11: =C9+C10 -> 9965.655 | D11: =D9+D10 -> 6205.406 | E11: =E9+E10 -> 5263.934 | F11: =F9+F10 -> 5840.102
A12: Income Taxes | B12: 1741.351 | C12: 1254.026 | D12: 797.415 | E12: 772.005 | F12: 723.875
A13: Net Income | B13: =B11-B12 -> 10981.204 | C13: =C11-C12 -> 8711.629 | D13: =D11-D12 -> 5407.991 | E13: =E11-E12 -> 4491.929 | F13: =F11-F12 -> 5116.227
A15: Statement of Cash Flows for the years ended 31 December
A16: Net Income / Loss | B16: 10981.2 | C16: 8711.631 | D16: 5407.99 | E16: 4491.924 | F16: 5116.228
A17: Depreciation & Amortization | B17: 16755.55 | C17: 15630.43 | D17: 14554.38 | E17: 14362.81 | F17: 12438.78
A18: Other Non-Cash Items | B18: -17131.26 | C18: -16947.62 | D18: -12571.93 | E18: -16070.39 | F18: -16920.42
A19: Total Non-Cash Items | B19: -375.709 | C19: -1317.193 | D19: 1982.458 | E19: -1707.579 | F19: -4481.641
A20: Change in Accounts Payable | B20: -8.039 | C20: 121.353 | D20: 93.502 | E20: -158.543 | F20: 145.115
A21: Change in Assets / Liabilities | B21: -1329.399 | C21: -346.327 | D21: -313.215 | E21: -544.031 | F21: -567.43
A22: Total Change in Assets/Liabilities | B22: -456.22 | C22: -33.075 | D22: -116.148 | E22: -758.087 | F22: -241.977
A23: Cash Flow from Operating Activities (CFO) | B23: =B16+B19+B22 -> 10149.271 | C23: =C16+C19+C22 -> 7361.363 | D23: =D16+D19+D22 -> 7274.3 | E23: =E16+E19+E22 -> 2026.258 | F23: =F16+F19+F22 -> 392.61
A24: Net Change in PP&E (Capex) | B24: -688.22 | C24: -439.538 | D24: -348.552 | E24: -407.729 | F24: -524.585
A25: Net Acquisitions / Divestitures | B25: -17.194 | C25: 0 | D25: 0 | E25: -757.387 | F25: -788.349
A26: Net Change in Short-term Investments | B26: 1747.102 | C26: -1742.246 | D26: 890.303 | E26: -911.276 | F26: 0
A27: Net Change in Investments – Total | B27: 1747.102 | C27: -1742.246 | D27: 890.303 | E27: -911.276 | F27: 0
A28: Cash Flow from Investing Activities | B28: =B24+B25+B26 -> 1041.688 | C28: =C24+C25+C26 -> -2181.784 | D28: =D24+D25+D26 -> 541.751 | E28: =E24+E25+E26 -> -2076.392 | F28: -1339.853
A29: Net Long-Term Debt | B29: -1833.45 | C29: 1394.46 | D29: – | E29: -700 | F29: -500
A30: Net Common Equity Issued / Repurchased | B30: -8460.202 | C30: -5430.859 | D30: -5875.357 | E30: 35.746 | F30: -425.608
A31: Cash Flow from Financing Activities | B31: -10345.62 | C31: -4074.427 | D31: -5950.803 | E31: -664.254 | F31: -1149.776
A32: Impact of exchange rates on cash, cash equivalents and restricted cash | B32: 386.52 | C32: -416.33 | D32: 82.68 | E32: -170.14 | F32: -86.74
A33: Net Cash Flow(CFO+CFI+CFF) | B33: 1231.86 | C33: 272.49 | D33: 2030.61 | E33: -1054.67 | F33: -2183.76
A34: Cash & Cash Equivalents at Beginning of Year | B34: 7807.34 | C34: 7118.52 | D34: 5170.58 | E34: 6055.11 | F34: 8238.87
A35: Cash & Cash Equivalents at End of Year | B35: 9425.72 | C35: 7391.01 | D35: 7201.19 | E35: 5000.44 | F35: 6055.11

Sheet Financials_The Walt Disney
A1: Statement of Profit or Loss for the years ended 31 December
A2: Annual Data (USD millions) | B2: 2025-12-31 | C2: 2024-12-31 | D2: 2023-12-31 | E2: 2022-12-31 | F2: 2021-12-31
A3: Revenue | B3: 94425 | C3: 91361 | D3: 88898 | E3: 82722 | F3: 67418
A4: Cost of Goods Sold | B4: 58766 | C4: 58698 | D4: 59201 | E4: 54401 | F4: 45131
A5: Gross Profit | B5: =B3-B4 -> 35659 | C5: =C3-C4 -> 32663 | D5: =D3-D4 -> 29697 | E5: =E3-E4 -> 28321 | F5: =F3-F4 -> 22287
A6: Research & Development Expenses | B6: – | C6: – | D6: – | E6: – | F6: –
A7: SG&A Expenses | B7: 16501 | C7: 15759 | D7: 15336 | E7: 16388 | F7: 13517
A8: Other Operating Income / Expenses | B8: – | C8: – | D8: – | E8: – | F8: –
A9: Operating Expenses | B9: 22646 | C9: 24344 | D9: 24597 | E9: 21788 | F9: 19282
A10: Operating Income | B10: =B5-B9 -> 13013 | C10: =C5-C9 -> 8319 | D10: =D5-D9 -> 5100 | E10: =E5-E9 -> 6533 | F10: =F5-F9 -> 3005
A11: Total Non-Operating Income / Expense | B11: -1010 | C11: -750 | D11: -331 | E11: -1248 | F11: -444
A12: Pre-Tax Income | B12: =B10+B11 -> 12003 | C12: =C10+C11 -> 7569 | D12: =D10+D11 -> 4769 | E12: =E10+E11 -> 5285 | F12: =F10+F11 -> 2561
A13: Income Taxes(expense or benefit) | B13: -1428 | C13: 1796 | D13: 1379 | E13: 1732 | F13: 25
A14: Income After Taxes | B14: =B12-B13 -> 13431 | C14: =C12-C13 -> 5773 | D14: =D12-D13 -> 3390 | E14: =E12-E13 -> 3553 | F14: =F12-F13 -> 2536
A15: Net income from continuing operations attributable to noncontrolling and redeemable noncontrolling interests | B15: -1027 | C15: -801 | D15: -1036 | E15: -408 | F15: 541
A16: Net Income | B16: =B14+B15 -> 12404 | C16: =C14+C15 -> 4972 | D16: =D14+D15 -> 2354 | E16: =E14+E15 -> 3145 | F16: 1995
A18: Statement of Cash Flows for the years ended 31 December
A19: Net Income / Loss | B19: 13431 | C19: 5773 | D19: 3390 | E19: 3553 | F19: 2536
A20: Depreciation & Amortization | B20: 6197 | C20: 8501 | D20: 8497 | E20: 5375 | F20: 5111
A21: Other Non-Cash Items | B21: -1097 | C21: 1310 | D21: -2198 | E21: -3414 | F21: -4275
A22: Total Non-Cash Items | B22: =B20+B21 -> 5100 | C22: =C20+C21 -> 9811 | D22: =D20+D21 -> 6299 | E22: =E20+E21 -> 1961 | F22: =F20+F21 -> 836
A23: Change in Accounts Receivable | B23: -283 | C23: -565 | D23: 358 | E23: 605 | F23: -357
A24: Change in Inventories | B24: -114 | C24: -42 | D24: -183 | E24: -420 | F24: 252
A25: Change in Assets / Liabilities | B25: -42 | C25: 265 | D25: -201 | E25: -707 | F25: 171
A26: Total Change in Assets/Liabilities | B26: -430 | C26: -1613 | D26: 177 | E26: 488 | F26: 2194
A27: Cash Flow from Operating Activities (CFO) | B27: =B19+B22+B26 -> 18101 | C27: =C19+C22+C26 -> 13971 | D27: =D19+D22+D26 -> 9866 | E27: =E19+E22+E26 -> 6002 | F27: =F19+F22+F26 -> 5566
A28: Net Change in Property, Plant & Equipment (Capex) | B28: -8024 | C28: -5412 | D28: -4969 | E28: -4943 | F28: -3578
A29: Net Change in Long-Term Investments | B29: -94 | C29: -1401 | D29: 458 | E29: 52 | F29: 337
A30: Investing Activities – Other | B30: 75 | C30: -68 | D30: -130 | E30: -117 | F30: 70
A31: Cash Flow from Investing Activities | B31: =B28+B29+B30 -> -8043 | C31: =C28+C29+C30 -> -6881 | D31: =D28+D29+D30 -> -4641 | E31: =E28+E29+E30 -> -5008 | F31: =F28+F29+F30 -> -3171
A32: Net Long-Term Debt | B32: -2678 | C32: -2932 | D32: -1592 | E32: -3683 | F32: -3673
A33: Net Current Debt | B33: -943 | C33: 1532 | D33: -191 | E33: -334 | F33: -26
A34: Net Common Equity Issued / Repurchased | B34: -3500 | C34: -2992 | D34: 0 | E34: 0 | F34: 435
A35: Dividends Paid | B35: -1803 | C35: -1366 | D35: 0 | E35: 0 | F35: 0
A36: Financial Activities – Other | B36: -1442 | C36: -9530 | D36: -941 | E36: -712 | F36: -1121
A37: Cash Flow from Financing Activities | B37: =B32+B33+B34+B36++B35 -> -10366 | C37: =C32+C33+C34+C36++C35 -> -15288 | D37: =D32+D33+D34+D36++D35 -> -2724 | E37: =E32+E33+E34+E36++E35 -> -4729 | F37: =F32+F33+F34+F36++F35 -> -4385
A38: Impact of exchange rates on cash, cash equivalents and restricted cash | B38: 5 | C38: 65 | D38: 73 | E38: -603 | F38: 30
A39: Net Cash Flow(CFO+CFI+CFF) | B39: =-(B27+B31+B37)-B38 -> 303 | C39: =-(C27+C31+C37)-C38 -> 8133 | D39: =-(D27+D31+D37)-D38 -> -2574 | E39: =-(E27+E31+E37)-E38 -> 4338 | F39: =-(F27+F31+F37)-F38 -> 1960
A40: Cash & Cash Equivalents at Beginning of Year | B40: 6102 | C40: 14235 | D40: 11661 | E40: 16003 | F40: 17954
A41: Cash & Cash Equivalents at End of Year | B41: =B40-B39 -> 5799 | C41: =C40-C39 -> 6102 | D41: =D40-D39 -> 14235 | E41: =E40-E39 -> 11665 | F41: =F40-F39 -> 15994

Sheet Ratios
B1: Financial Performance and Cash Flow Analysis
D2: Netflix | R2: The Walt Disney Company
B3: Profitability Ratios (%) | O3: Profitability Ratios (%)
B4: Metric | D4: 2025 | E4: =D4-1 -> 2024 | F4: =E4-1 -> 2023 | G4: =F4-1 -> 2022 | H4: =G4-1 -> 2021 | O4: Metric | Q4: 2025 | R4: =Q4-1 -> 2024 | S4: =R4-1 -> 2023 | T4: =S4-1 -> 2022 | U4: =T4-1 -> 2021
B5: Operating Margin | D5: =Financials_Netflix!B9/Financials_Netflix!B3 -> 0.29494709 | E5: =Financials_Netflix!C9/Financials_Netflix!C3 -> 0.26711168 | F5: =Financials_Netflix!D9/Financials_Netflix!D3 -> 0.2062077 | G5: =Financials_Netflix!E9/Financials_Netflix!E3 -> 0.17816663 | H5: =Financials_Netflix!F9/Financials_Netflix!F3 -> 0.20858446 | O5: Operating Margin | Q5: ='Financials_The Walt Disney'!B10/'Financials_The Walt Disney'!B3 -> 0.13781308 | R5: ='Financials_The Walt Disney'!C10/'Financials_The Walt Disney'!C3 -> 0.091056359 | S5: ='Financials_The Walt Disney'!D10/'Financials_The Walt Disney'!D3 -> 0.05736912 | T5: ='Financials_The Walt Disney'!E10/'Financials_The Walt Disney'!E3 -> 0.078975363 | U5: ='Financials_The Walt Disney'!F10/'Financials_The Walt Disney'!F3 -> 0.044572666
B6: Net Profit Margin | D6: =Financials_Netflix!B13/Financials_Netflix!B3 -> 0.24303818 | E6: =Financials_Netflix!C13/Financials_Netflix!C3 -> 0.2233696 | F6: =Financials_Netflix!D13/Financials_Netflix!D3 -> 0.16036364 | G6: =Financials_Netflix!E13/Financials_Netflix!E3 -> 0.14207974 | H6: =Financials_Netflix!F13/Financials_Netflix!F3 -> 0.17227606 | O6: Net Profit Margin | Q6: ='Financials_The Walt Disney'!B16/'Financials_The Walt Disney'!B3 -> 0.13136352 | R6: ='Financials_The Walt Disney'!C16/'Financials_The Walt Disney'!C3 -> 0.054421471 | S6: ='Financials_The Walt Disney'!D16/'Financials_The Walt Disney'!D3 -> 0.026479786 | T6: ='Financials_The Walt Disney'!E16/'Financials_The Walt Disney'!E3 -> 0.038018907 | U6: ='Financials_The Walt Disney'!F16/'Financials_The Walt Disney'!F3 -> 0.029591504
B9: Free Cash Flow Ratios(%) | O9: Free Cash Flow Ratios(%)
B10: Metric | E10: 2025 | F10: =E10-1 -> 2024 | G10: =F10-1 -> 2023 | H10: =G10-1 -> 2022 | I10: =H10-1 -> 2021 | O10: Metric | R10: 2025 | S10: =R10-1 -> 2024 | T10: =S10-1 -> 2023 | U10: =T10-1 -> 2022 | V10: =U10-1 -> 2021
B11: Free Cash Flow (USD mn) | E11: =(Financials_Netflix!B23+Financials_Netflix!B24) -> 9461.051 | F11: =(Financials_Netflix!C23+Financials_Netflix!C24) -> 6921.825 | G11: =(Financials_Netflix!D23+Financials_Netflix!D24) -> 6925.748 | H11: =(Financials_Netflix!E23+Financials_Netflix!E24) -> 1618.529 | I11: =(Financials_Netflix!F23+Financials_Netflix!F24) -> -131.975 | O11: Free Cash Flow (USD mn) | R11: ='Financials_The Walt Disney'!B27+'Financials_The Walt Disney'!B28 -> 10077 | S11: ='Financials_The Walt Disney'!C27+'Financials_The Walt Disney'!C28 -> 8559 | T11: ='Financials_The Walt Disney'!D27+'Financials_The Walt Disney'!D28 -> 4897 | U11: ='Financials_The Walt Disney'!E27+'Financials_The Walt Disney'!E28 -> 1059 | V11: ='Financials_The Walt Disney'!F27+'Financials_The Walt Disney'!F28 -> 1988
B12: Free Cash Flow Margin (%) | E12: =Ratios!E11/Financials_Netflix!B3 -> 0.20939386 | F12: =Ratios!F11/Financials_Netflix!C3 -> 0.17747832 | G12: =Ratios!G11/Financials_Netflix!D3 -> 0.20536982 | H12: =Ratios!H11/Financials_Netflix!E3 -> 0.05119408 | I12: =Ratios!I11/Financials_Netflix!F3 -> -0.0044439259 | O12: Free Cash Flow Margin (%) | R12: =R11/'Financials_The Walt Disney'!B3 -> 0.10671962 | S12: =S11/'Financials_The Walt Disney'!C3 -> 0.0936833 | T12: =T11/'Financials_The Walt Disney'!D3 -> 0.055085604 | U12: =U11/'Financials_The Walt Disney'!E3 -> 0.012801915 | V12: =V11/'Financials_The Walt Disney'!F3 -> 0.029487674
B15: Cash Flow Quality Ratios(%) | O15: Cash Flow Quality Ratios(%)
B16: Metric | F16: 2025 | G16: =F16-1 -> 2024 | H16: =G16-1 -> 2023 | I16: =H16-1 -> 2022 | J16: =I16-1 -> 2021 | O16: Metric | S16: 2025 | T16: =S16-1 -> 2024 | U16: =T16-1 -> 2023 | V16: =U16-1 -> 2022 | W16: =V16-1 -> 2021
B17: Operating Cash Flow / Net Income(x) | F17: =Financials_Netflix!B23/Financials_Netflix!B13 -> 0.92424027 | G17: =Financials_Netflix!C23/Financials_Netflix!C13 -> 0.84500419 | H17: =Financials_Netflix!D23/Financials_Netflix!D13 -> 1.3451021 | I17: =Financials_Netflix!E23/Financials_Netflix!E13 -> 0.45108861 | J17: =Financials_Netflix!F23/Financials_Netflix!F13 -> 0.07673819 | O17: Operating Cash Flow / Net Income | S17: ='Financials_The Walt Disney'!B27/'Financials_The Walt Disney'!B16 -> 1.4592873 | T17: ='Financials_The Walt Disney'!C27/'Financials_The Walt Disney'!C16 -> 2.8099356 | U17: ='Financials_The Walt Disney'!D27/'Financials_The Walt Disney'!D16 -> 4.191164 | V17: ='Financials_The Walt Disney'!E27/'Financials_The Walt Disney'!E16 -> 1.9084261 | W17: ='Financials_The Walt Disney'!F27/'Financials_The Walt Disney'!F16 -> 2.7899749
B18: Operating Cash Flow Margin | F18: =Financials_Netflix!B23/Financials_Netflix!B3 -> 0.22462568 | G18: =Financials_Netflix!C23/Financials_Netflix!C3 -> 0.18874825 | H18: =Financials_Netflix!D23/Financials_Netflix!D3 -> 0.21570546 | I18: =Financials_Netflix!E23/Financials_Netflix!E3 -> 0.06409055 | J18: =Financials_Netflix!F23/Financials_Netflix!F3 -> 0.013220153 | O18: Operating Cash Flow Margin | S18: ='Financials_The Walt Disney'!B27/'Financials_The Walt Disney'!B3 -> 0.19169711 | T18: ='Financials_The Walt Disney'!C27/'Financials_The Walt Disney'!C3 -> 0.15292083 | U18: ='Financials_The Walt Disney'!D27/'Financials_The Walt Disney'!D3 -> 0.11098112 | V18: ='Financials_The Walt Disney'!E27/'Financials_The Walt Disney'!E3 -> 0.072556273 | W18: ='Financials_The Walt Disney'!F27/'Financials_The Walt Disney'!F3 -> 0.082559554
B19: Cash Conversion Ratio(x) | F19: =Financials_Netflix!B23/Financials_Netflix!B9 -> 0.76157958 | G19: =Financials_Netflix!C23/Financials_Netflix!C9 -> 0.70662672 | H19: =Financials_Netflix!D23/Financials_Netflix!D9 -> 1.0460592 | I19: =Financials_Netflix!E23/Financials_Netflix!E9 -> 0.35972253 | J19: =Financials_Netflix!F23/Financials_Netflix!F9 -> 0.063380336 | O19: Cash Conversion Ratio(x) | S19: ='Financials_The Walt Disney'!B27/'Financials_The Walt Disney'!B10 -> 1.3909936 | T19: ='Financials_The Walt Disney'!C27/'Financials_The Walt Disney'!C10 -> 1.6794086 | U19: ='Financials_The Walt Disney'!D27/'Financials_The Walt Disney'!D10 -> 1.9345098 | V19: ='Financials_The Walt Disney'!E27/'Financials_The Walt Disney'!E10 -> 0.91872034 | W19: ='Financials_The Walt Disney'!F27/'Financials_The Walt Disney'!F10 -> 1.8522463
K22: (Subscription / Service-Based Businesses)
K23: Metric | M23: Weak | O23: Average | P23: Strong
K24: Operating Margin (%) | M24: <5 | O24: 5% – 15% | P24: > 15%
K25: Net Profit Margin (%) | M25: <3 | O25: 3% – 10% | P25: > 10%
K26: CFO / Net Income | M26: <0.8x | O26: 0.8x – 1.2x | P26: > 1.2x
K27: Operating Cash Flow Margin (%) | M27: <5 | O27: 5% – 15% | P27: > 15%
K28: Free Cash Flow Margin (%) | M28: <0 | O28: 0% – 10% | P28: > 10%
K29: Cash Conversion Ratio(x) | M29: < 0.8x | O29: 0.8x – 1.2x | P29: >1.2x
K30: * Disclaimer / Note:
K31: Benchmark ranges are indicative reference thresholds commonly used in financial
K32: statement analysis for subscription-led and service-based businesses. They are not precise
K33: industry averages and are intended solely to support relative performance interpretation.

Sheet Trend_Analysis
B1: Netflix | K1: The Walt Disney Company
B2: Ratio | C2: 2021 | D2: =C2+1 -> 2022 | E2: =D2+1 -> 2023 | F2: =E2+1 -> 2024 | G2: =F2+1 -> 2025 | H2: Trend | I2: Interpretation | K2: Ratio | L2: 2021 | M2: =L2+1 -> 2022 | N2: =M2+1 -> 2023 | O2: =N2+1 -> 2024 | P2: =O2+1 -> 2025 | Q2: Trend | R2: Interpretation
B3: Operating Margin(%) | C3: → | D3: ↓ | E3: ↑ | F3: ↑ | G3: ↑ | H3: ↑Improving momentum | I3: Netflix operates a pure subscription-based digital model, while Disney runs a diversified, vertically integrated business spanning streaming, studios, parks, and consumer products. Despite generating nearly 20× lower revenue than Disney, Netflix delivers comparable profitability due to its significantly lower cost base, particularly in COGS, as it avoids physical infrastructure and asset-heavy operations. | K3: Operating Margin(%) | L3: → | M3: ↑ | N3: ↓ | O3: ↑ | P3: ↑ | Q3: ↑Improving momentum | R3: Here the operating margin have improved from the year 2021 till 2025,reflecting recovery in core businesses such as parks and media. However, margins remain structurally constrained by Disney’s diversified and asset-heavy operating model, where fixed costs and operating complexity limit scalability compared to digital-first peers.
B4: Net Profit Margin | C4: → | D4: ↓ | E4: ↑ | F4: ↑ | G4: ↑ | H4: ↑Improving momentum | I4: Operating and net margins show a consistent upward trend, reflecting improving operating leverage and disciplined cost control. This highlights Netflix’s ability to scale profits efficiently, even without the revenue breadth that Disney enjoys. | K4: Net Profit Margin | L4: → | M4: → | N4: ↓ | O4: ↑ | P4: ↑ | Q4: ↑Improving momentum | R4: Net profit margins have improved in line with operating performance, indicating that earnings recovery is being driven by core business operations. However, profitability remains sensitive to depreciation, interest expense, and business mix, reflecting the earnings variability inherent in Disney’s diversified operating structure.
B5: CFO/Net Income | C5: → | D5: ↑ | E5: ↑ | F5: ↓ | G5: ↑ | H5: ↕ Volatile (Improving bias) | I5: This ratio shows volatility with an improving bias, highlighting timing differences between cash spending on content and profit recognition. While short-term fluctuations persist, the overall trend suggests that reported earnings are increasingly supported by operating cash flows rather than accounting adjustments. | K5: CFO/Net Income | L5: → | M5: ↓ | N5: ↑ | O5: ↓ | P5: ↓ | Q5: ↕ Volatile | R5: Operating cash flow consistently exceeds net income, indicating that reported earnings are cash-backed. However, the ratio shows pronounced volatility, reflecting timing effects from working capital movements and the capital-intensive nature of Disney’s diversified operations rather than stable cash conversion.
B6: FCF Margin(%) | C6: ↓ | D6: → | E6: ↑ | F6: ↓ | G6: ↑ | H6: ↕ Volatile | I6: Free cash flow margin remains volatile, reflecting Netflix’s ongoing reinvestment in content. However, the positive directional bias indicates a gradual shift toward stronger free cash generation, suggesting that growth is becoming more internally funded rather than dependent on external financing. | K6: FCF Margin(%) | L6: → | M6: ↓ | N6: ↑ | O6: ↑ | P6: ↑ | Q6: ↑Improving momentum | R6: The improvement in free cash flow margin reflects higher operating cash inflows alongside more normalised capital spending. This suggests that recent cash generation is supported by operating performance rather than deferred investment, although free cash flow remains closely linked to Disney’s ongoing reinvestment requirements across parks, content, and infrastructure.
B7: Operating Cash Flow / Net Income(x) | C7: → | D7: ↑ | E7: ↑ | F7: ↓ | G7: → | H7: → Stabilising | I7: The stabilising trend in this ratio signals improving alignment between reported profits and underlying cash generation. This indicates that Netflix’s earnings quality is strengthening, with operating cash flows increasingly matching accounting profitability. | K7: Operating Cash Flow / Net Income(x) | L7: → | M7: ↓ | N7: ↑ | O7: → | P7: ↓ | Q7: → Stabilising | R7: Operating cash flow remains higher than net income, indicating that earnings continue to be supported by cash generation. The ratio has become less erratic, suggesting a more stable relationship between profits and operating cash flows.
B8: Operating Cash Flow Margin | C8: → | D8: ↑ | E8: ↑ | F8: ↓ | G8: ↑ | H8: ↑Improving momentum | I8: The improving trend in operating cash flow margin confirms that revenue growth is translating into stronger cash generation. Netflix’s asset-light, subscription-driven model enables efficient cash extraction from operations compared to Disney’s diversified structure, which requires heavier ongoing investment. | K8: Operating Cash Flow Margin | L8: → | M8: ↓ | N8: ↑ | O8: ↑ | P8: ↑ | Q8: ↑Improving momentum | R8: Operating cash flow margin is trending upward, showing improved cash generation from core operations. This indicates that operating performance is increasingly translating into cash, despite the capital-intensive nature of Disney’s business.
B9: Cash Conversion Ratio(x) | C9: → | D9: ↑ | E9: ↑ | F9: ↓ | G9: ↑ | H9: ↑Improving momentum | I9: Cash conversion has improved from weaker levels, indicating better alignment between reported earnings and cash generation. However, the ratio remains below optimal, suggesting that while earnings quality is improving, profits are not yet fully translating into cash. | K9: Cash Conversion Ratio(x) | L9: → | M9: ↓ | N9: → | O9: ↓ | P9: ↓ | Q9: ↓ Deteriorating | R9: Cash conversion has moderated from earlier levels. While earnings continue to convert into cash, the downward trend reflects higher reinvestment and working capital absorption associated with Disney’s diversified operations.

Sheet KPIs_Qs
C1: Netflix | K1: The Walt Disney Company
A2: KPIs (Latest Year – 2025) | B2: 2025 | C2: 2024 | D2: 2023 | E2: 2022 | F2: 2021 | J2: 2025 | K2: 2024 | L2: 2023 | M2: 2022 | N2: 2021
A3: Operating Margin (%) | B3: 0.29494709 | C3: 0.26711168 | D3: 0.2062077 | E3: 0.17816663 | F3: 0.20858446 | J3: 0.13781308 | K3: 0.091056359 | L3: 0.05736912 | M3: 0.078975363 | N3: 0.044572666
B5: 0.92424027 | C5: 0.84500419 | D5: 1.3451021 | E5: 0.45108861 | F5: 0.07673819 | J5: 1.4592873 | K5: 2.8099356 | L5: 4.191164 | M5: 1.9084261 | N5: 2.7899749
A6: Free Cash Flow Margin (%) | B6: 0.20939386 | C6: 0.17747832 | D6: 0.20536982 | E6: 0.05119408 | F6: -0.0044439259 | J6: 0.10671962 | K6: 0.0936833 | L6: 0.055085604 | M6: 0.012801915 | N6: 0.029487674
A7: CFO / Net Income (x) | B7: 0.92424027 | C7: 0.84500419 | D7: 1.3451021 | E7: 0.45108861 | F7: 0.07673819 | J7: 1.4592873 | K7: 2.8099356 | L7: 4.191164 | M7: 1.9084261 | N7: 2.7899749
A8: Cash Conversion Ratio (x) | B8: 0.76157958 | C8: 0.70662672 | D8: 1.0460592 | E8: 0.35972253 | F8: 0.063380336 | J8: 1.3909936 | K8: 1.6794086 | L8: 1.9345098 | M8: 0.91872034 | N8: 1.8522463
A11: Key Questions Addressed by the Dashboard
A12: • How profitable are core operations in the latest year (2025)?
A13: • How much profit remains after all costs and taxes?
A14: • How effectively does revenue convert into operating cash?
A15: • How much cash is left after reinvestment (free cash flow)?
A16: • Are reported earnings supported by operating cash flows? | J16: Years | K16: 2025 | L16: 2024 | M16: 2023 | N16: 2022 | O16: 2021
A17: • How efficiently are accounting profits converted into cash? | J17: Netflix | K17: =Ratios!F$18 -> 0.22462568 | L17: =Ratios!G$18 -> 0.18874825 | M17: =Ratios!H$18 -> 0.21570546 | N17: =Ratios!I$18 -> 0.06409055 | O17: =Ratios!J$18 -> 0.013220153
J18: The Walt Disney Company | K18: =Ratios!S$18 -> 0.19169711 | L18: =Ratios!T$18 -> 0.15292083 | M18: =Ratios!U$18 -> 0.11098112 | N18: =Ratios!V$18 -> 0.072556273 | O18: =Ratios!W$18 -> 0.082559554
J20: Years | K20: Netflix | L20: The Walt Disney Company
J21: 2025 | K21: =Ratios!F$18 -> 0.22462568 | L21: =Ratios!S$18 -> 0.19169711
J22: 2024 | K22: =Ratios!G$18 -> 0.18874825 | L22: =Ratios!T$18 -> 0.15292083
J23: 2023 | K23: =Ratios!H$18 -> 0.21570546 | L23: =Ratios!U$18 -> 0.11098112
J24: 2022 | K24: =Ratios!I$18 -> 0.06409055 | L24: =Ratios!V$18 -> 0.072556273
J25: 2021 | K25: =Ratios!J$18 -> 0.013220153 | L25: =Ratios!W$18 -> 0.082559554
B27: Net Profit Margin (2025) | C27: 2025 | D27: 2024 | E27: 2023 | F27: 2022 | G27: 2021
B28: Netflix | C28: 0.24303818 | D28: 0.2233696 | E28: 0.16036364 | F28: 0.14207974 | G28: 0.17227606
B29: The Walt Disney Company | C29: 0.13136352 | D29: 0.054421471 | E29: 0.026479786 | F29: 0.038018907 | G29: 0.029591504
J33: Years | K33: Netflix | L33: The Walt Disney Company
J34: 2025 | K34: 0.20939386 | L34: 0.10671962
J35: 2024 | K35: 0.17747832 | L35: 0.0936833
J36: 2023 | K36: 0.20536982 | L36: 0.055085604
J37: 2022 | K37: 0.05119408 | L37: 0.012801915
J38: 2021 | K38: -0.0044439259 | L38: 0.029487674
S39: Benchmark
J40: Are reported earnings supported by operating cash flows | R40: 2021 | S40: 1
J41: Years | K41: Netflix | L41: The Walt Disney Company | M41: Benchmark | N41: number > 1 → cash is strong | R41: =R40+1 -> 2022 | S41: 1
J42: 2025 | K42: 0.92424027 | L42: 1.4592873 | M42: 1 | N42: If < 1 → profit not fully backed by cash | R42: =R41+1 -> 2023 | S42: 1
J43: 2024 | K43: 0.84500419 | L43: 2.8099356 | M43: 1 | R43: =R42+1 -> 2024 | S43: 1
J44: 2023 | K44: 1.3451021 | L44: 4.191164 | M44: 1 | R44: =R43+1 -> 2025 | S44: 1
J45: 2022 | K45: 0.45108861 | L45: 1.9084261 | M45: 1
J46: 2021 | K46: 0.07673819 | L46: 2.7899749 | M46: 1
J48: • How efficiently are accounting profits converted into cash?
J49: Years | K49: Netflix | L49: The Walt Disney Company | M49: Weak | N49: Strong
...

Sheet Dashboard
H36: =
